{"uuid": "282855be-e507-4a9a-ba5a-79bf9eb5ab83", "children": ["664bec19-9fd0-410c-9573-0374db838d06"], "befores": [{"name": "driver", "status": "broken", "statusDetails": {"message": "selenium.common.exceptions.WebDriverException: Message: An unknown server-side error occurred while processing the command. Original error: Cannot start the 'ru.cashtoyou.app' application. Consider checking the driver's troubleshooting documentation. Original error: Error executing adbExec. Original error: 'Command '/Users/evgenijpuckov/Library/Android/sdk/platform-tools/adb -P 5037 -s emulator-5554 shell am start-activity -W -n ru.cashtoyou.app/ru.cashtoyou.app.ui.CtyMainActivity -S -a android.intent.action.MAIN -c android.intent.category.LAUNCHER -f 0x10200000' timed out after 20000ms'. Try to increase the 20000ms adb execution timeout represented by 'adbExecTimeout' capability\nStacktrace:\nUnknownError: An unknown server-side error occurred while processing the command. Original error: Cannot start the 'ru.cashtoyou.app' application. Consider checking the driver's troubleshooting documentation. Original error: Error executing adbExec. Original error: 'Command '/Users/evgenijpuckov/Library/Android/sdk/platform-tools/adb -P 5037 -s emulator-5554 shell am start-activity -W -n ru.cashtoyou.app/ru.cashtoyou.app.ui.CtyMainActivity -S -a android.intent.action.MAIN -c android.intent.category.LAUNCHER -f 0x10200000' timed out after 20000ms'. Try to increase the 20000ms adb execution timeout represented by 'adbExecTimeout' capability\n    at getResponseForW3CError (/usr/local/lib/node_modules/appium/node_modules/@appium/base-driver/lib/protocol/errors.js:1143:9)\n    at asyncHandler (/usr/local/lib/node_modules/appium/node_modules/@appium/base-driver/lib/protocol/protocol.js:487:57)\n", "trace": "  File \"/Users/evgenijpuckov/PycharmProjects/QA_Auto_Appium/.venv/lib/python3.12/site-packages/pluggy/_callers.py\", line 38, in run_old_style_hookwrapper\n    res = yield\n          ^^^^^\n  File \"/Users/evgenijpuckov/PycharmProjects/QA_Auto_Appium/.venv/lib/python3.12/site-packages/pluggy/_callers.py\", line 139, in _multicall\n    teardown.throw(exception)\n  File \"/Users/evgenijpuckov/PycharmProjects/QA_Auto_Appium/.venv/lib/python3.12/site-packages/_pytest/setuponly.py\", line 36, in pytest_fixture_setup\n    return (yield)\n            ^^^^^\n  File \"/Users/evgenijpuckov/PycharmProjects/QA_Auto_Appium/.venv/lib/python3.12/site-packages/pluggy/_callers.py\", line 121, in _multicall\n    res = hook_impl.function(*args)\n          ^^^^^^^^^^^^^^^^^^^^^^^^^\n  File \"/Users/evgenijpuckov/PycharmProjects/QA_Auto_Appium/.venv/lib/python3.12/site-packages/_pytest/fixtures.py\", line 1195, in pytest_fixture_setup\n    result = call_fixture_func(fixturefunc, request, kwargs)\n             ^^^^^^^^^^^^^^^^^^^^^^^^^^^^^^^^^^^^^^^^^^^^^^^\n  File \"/Users/evgenijpuckov/PycharmProjects/QA_Auto_Appium/.venv/lib/python3.12/site-packages/_pytest/fixtures.py\", line 922, in call_fixture_func\n    fixture_result = next(generator)\n                     ^^^^^^^^^^^^^^^\n  File \"/Users/evgenijpuckov/PycharmProjects/QA_Auto_Appium/mobile_project/Android_CTY/conftest.py\", line 25, in driver\n    app = webdriver.Remote(appium_server_url, options=capabilities_options)\n          ^^^^^^^^^^^^^^^^^^^^^^^^^^^^^^^^^^^^^^^^^^^^^^^^^^^^^^^^^^^^^^^^^\n  File \"/Users/evgenijpuckov/PycharmProjects/QA_Auto_Appium/.venv/lib/python3.12/site-packages/appium/webdriver/webdriver.py\", line 253, in __init__\n    super().__init__(\n  File \"/Users/evgenijpuckov/PycharmProjects/QA_Auto_Appium/.venv/lib/python3.12/site-packages/selenium/webdriver/remote/webdriver.py\", line 250, in __init__\n    self.start_session(capabilities)\n  File \"/Users/evgenijpuckov/PycharmProjects/QA_Auto_Appium/.venv/lib/python3.12/site-packages/appium/webdriver/webdriver.py\", line 344, in start_session\n    response = self.execute(RemoteCommand.NEW_SESSION, w3c_caps)\n               ^^^^^^^^^^^^^^^^^^^^^^^^^^^^^^^^^^^^^^^^^^^^^^^^^\n  File \"/Users/evgenijpuckov/PycharmProjects/QA_Auto_Appium/.venv/lib/python3.12/site-packages/selenium/webdriver/remote/webdriver.py\", line 429, in execute\n    self.error_handler.check_response(response)\n  File \"/Users/evgenijpuckov/PycharmProjects/QA_Auto_Appium/.venv/lib/python3.12/site-packages/selenium/webdriver/remote/errorhandler.py\", line 232, in check_response\n    raise exception_class(message, screen, stacktrace)\n"}, "start": 1759922019467, "stop": 1759922077560}], "start": 1759922019467, "stop": 1759922077716}