{"uuid": "77c04f68-e870-4e3c-a5f0-d26b197e95c8", "children": ["a32e8232-9390-40e8-a599-be61519830d2"], "befores": [{"name": "driver", "status": "broken", "statusDetails": {"message": "selenium.common.exceptions.WebDriverException: Message: An unknown server-side error occurred while processing the command. Original error: The instrumentation process cannot be initialized. Make sure the application under test does not crash and investigate the logcat output.\nStacktrace:\nUnknownError: An unknown server-side error occurred while processing the command. Original error: The instrumentation process cannot be initialized. Make sure the application under test does not crash and investigate the logcat output.\n    at getResponseForW3CError (/usr/local/lib/node_modules/appium/node_modules/@appium/base-driver/lib/protocol/errors.js:1143:9)\n    at asyncHandler (/usr/local/lib/node_modules/appium/node_modules/@appium/base-driver/lib/protocol/protocol.js:487:57)\n", "trace": "  File \"/Users/evgenijpuckov/PycharmProjects/QA_Auto_Appium/.venv/lib/python3.12/site-packages/pluggy/_callers.py\", line 38, in run_old_style_hookwrapper\n    res = yield\n          ^^^^^\n  File \"/Users/evgenijpuckov/PycharmProjects/QA_Auto_Appium/.venv/lib/python3.12/site-packages/pluggy/_callers.py\", line 139, in _multicall\n    teardown.throw(exception)\n  File \"/Users/evgenijpuckov/PycharmProjects/QA_Auto_Appium/.venv/lib/python3.12/site-packages/_pytest/setuponly.py\", line 36, in pytest_fixture_setup\n    return (yield)\n            ^^^^^\n  File \"/Users/evgenijpuckov/PycharmProjects/QA_Auto_Appium/.venv/lib/python3.12/site-packages/pluggy/_callers.py\", line 121, in _multicall\n    res = hook_impl.function(*args)\n          ^^^^^^^^^^^^^^^^^^^^^^^^^\n  File \"/Users/evgenijpuckov/PycharmProjects/QA_Auto_Appium/.venv/lib/python3.12/site-packages/_pytest/fixtures.py\", line 1195, in pytest_fixture_setup\n    result = call_fixture_func(fixturefunc, request, kwargs)\n             ^^^^^^^^^^^^^^^^^^^^^^^^^^^^^^^^^^^^^^^^^^^^^^^\n  File \"/Users/evgenijpuckov/PycharmProjects/QA_Auto_Appium/.venv/lib/python3.12/site-packages/_pytest/fixtures.py\", line 922, in call_fixture_func\n    fixture_result = next(generator)\n                     ^^^^^^^^^^^^^^^\n  File \"/Users/evgenijpuckov/PycharmProjects/QA_Auto_Appium/mobile_project/Android_CTY/conftest.py\", line 24, in driver\n    app = webdriver.Remote(appium_server_url, options=capabilities_options)\n          ^^^^^^^^^^^^^^^^^^^^^^^^^^^^^^^^^^^^^^^^^^^^^^^^^^^^^^^^^^^^^^^^^\n  File \"/Users/evgenijpuckov/PycharmProjects/QA_Auto_Appium/.venv/lib/python3.12/site-packages/appium/webdriver/webdriver.py\", line 253, in __init__\n    super().__init__(\n  File \"/Users/evgenijpuckov/PycharmProjects/QA_Auto_Appium/.venv/lib/python3.12/site-packages/selenium/webdriver/remote/webdriver.py\", line 250, in __init__\n    self.start_session(capabilities)\n  File \"/Users/evgenijpuckov/PycharmProjects/QA_Auto_Appium/.venv/lib/python3.12/site-packages/appium/webdriver/webdriver.py\", line 344, in start_session\n    response = self.execute(RemoteCommand.NEW_SESSION, w3c_caps)\n               ^^^^^^^^^^^^^^^^^^^^^^^^^^^^^^^^^^^^^^^^^^^^^^^^^\n  File \"/Users/evgenijpuckov/PycharmProjects/QA_Auto_Appium/.venv/lib/python3.12/site-packages/selenium/webdriver/remote/webdriver.py\", line 429, in execute\n    self.error_handler.check_response(response)\n  File \"/Users/evgenijpuckov/PycharmProjects/QA_Auto_Appium/.venv/lib/python3.12/site-packages/selenium/webdriver/remote/errorhandler.py\", line 232, in check_response\n    raise exception_class(message, screen, stacktrace)\n"}, "start": 1761476051688, "stop": 1761476076056}], "start": 1761476051688, "stop": 1761476076196}